<?xml version="1.0" encoding="utf-8"?>
<!--Aqui comienza el robot-->
<robot name="omni_robot">

    <link name="base_footprint"/>

    <joint name="base_joint" type="fixed">
        <parent link="base_footprint"/>
        <child link="base_link"/>
        <origin xyz="0 0 0.095" rpy="0 0 0"/>
    </joint>

    <link name="base_link">
        <visual>
            <origin xyz="0.0 0.0 0.0" rpy="0 0 0" />
            <geometry>
                <box size="0.25 0.15 0.1" />
            </geometry>
            <material name="red">
                <color rgba="1 0.1 0.1 1.0" />
            </material>
        </visual>
        <collision>
            <origin xyz="0.0 0.0 -0.05" rpy="0 0 0" />
            <geometry>
                <box size="0.25 0.15 0.095" />
            </geometry>
        </collision>
        <inertial>
            <origin xyz="0 0 0" rpy="0 0 0"/>
            <mass value="1"/>
            <inertia ixx="1.0" ixy="0.0" ixz="0.0" 
                iyy="1.0" iyz="0.0" izz="1.0"/>
        </inertial>
    </link>

    <link name="wheel_left_front">
        <visual>
            <origin xyz="0.0 0.0 0.0" rpy="0 0 0" />
            <geometry>
                <cylinder length="0.05" radius="0.06"/>
            </geometry>
            <material name="grey">
                <color rgba="0.1 0.1 0.1 1.0" />
            </material>
        </visual>
        <collision>
            <origin xyz="0.0 0.0 0.0" rpy="0 0 0" />
            <geometry>
                <cylinder length="0.045" radius="0.06"/>
            </geometry>
        </collision>
        <inertial>
            <origin xyz="0 0 0" rpy="0 0 0"/>
            <mass value="1"/>
            <inertia ixx="1.0" ixy="0.0" ixz="0.0" 
                iyy="1.0" iyz="0.0" izz="1.0"/>
        </inertial>
    </link>

    <joint name="wheel_left_front_joint" type="continuous">
        <origin xyz="0.1 0.1 -0.035" rpy="1.5708 0  0" />
        <parent link="base_link" />
        <child link="wheel_left_front" />
        <axis xyz="0 0 1" />
    </joint>

    <link name="wheel_rigth_front">
        <visual>
            <origin xyz="0.0 0.0 0.0" rpy="0 0 0" />
            <geometry>
                <cylinder length="0.05" radius="0.06"/>
            </geometry>
            <material name="grey">
                <color rgba="0.1 0.1 0.1 1.0" />
            </material>
        </visual>
        <collision>
            <origin xyz="0.0 0.0 0.0" rpy="0 0 0" />
            <geometry>
                <cylinder length="0.045" radius="0.06"/>
            </geometry>
        </collision>
        <inertial>
            <origin xyz="0 0 0" rpy="0 0 0"/>
            <mass value="1"/>
            <inertia ixx="1.0" ixy="0.0" ixz="0.0" 
                iyy="1.0" iyz="0.0" izz="1.0"/>
        </inertial>
    </link>

    <joint name="wheel_rigth_front_joint" type="continuous">
        <origin xyz="0.1 -0.1 -0.035" rpy="1.5708 0  0" />
        <parent link="base_link" />
        <child link="wheel_rigth_front" />
        <axis xyz="0 0 1" />
    </joint>

    <link name="wheel_left_back">
        <visual>
            <origin xyz="0.0 0.0 0.0" rpy="0 0 0" />
            <geometry>
                <cylinder length="0.05" radius="0.06"/>
            </geometry>
            <material name="grey">
                <color rgba="0.1 0.1 0.1 1.0" />
            </material>
        </visual>
        <collision>
            <origin xyz="0.0 0.0 0.0" rpy="0 0 0" />
            <geometry>
                <cylinder length="0.045" radius="0.06"/>
            </geometry>
        </collision>
        <inertial>
            <origin xyz="0 0 0" rpy="0 0 0"/>
            <mass value="1"/>
            <inertia ixx="1.0" ixy="0.0" ixz="0.0" 
                iyy="1.0" iyz="0.0" izz="1.0"/>
        </inertial>
    </link>

    <joint name="wheel_left_back_joint" type="continuous">
        <origin xyz="-0.1 0.1 -0.035" rpy="1.5708 0  0" />
        <parent link="base_link" />
        <child link="wheel_left_back" />
        <axis xyz="0 0 1" />
    </joint>

    <link name="wheel_rigth_back">
        <visual>
            <origin xyz="0.0 0.0 0.0" rpy="0 0 0" />
            <geometry>
                <cylinder length="0.05" radius="0.06"/>
            </geometry>
            <material name="grey">
                <color rgba="0.1 0.1 0.1 1.0" />
            </material>
        </visual>
        <collision>
            <origin xyz="0.0 0.0 0.0" rpy="0 0 0" />
            <geometry>
                <cylinder length="0.045" radius="0.06"/>
            </geometry>
        </collision>
        <inertial>
            <origin xyz="0 0 0" rpy="0 0 0"/>
            <mass value="1"/>
            <inertia ixx="1.0" ixy="0.0" ixz="0.0" 
                iyy="1.0" iyz="0.0" izz="1.0"/>
        </inertial>
    </link>

    <joint name="wheel_rigth_back_joint" type="continuous">
        <origin xyz="-0.1 -0.1 -0.035" rpy="1.5708 0  0" />
        <parent link="base_link" />
        <child link="wheel_rigth_back" />
        <axis xyz="0 0 1" />
    </joint>


    <link name="lidar_link">
            <visual>
                <geometry>
                    <cylinder radius="0.05" length="0.05" />
                </geometry>
                <origin xyz="0 0 0" rpy="0 0 0" />
                <material name="grey" />
            </visual>
            <collision>
                <geometry>
                    <cylinder radius="0.1" length="0.05" />
                </geometry>
                    <origin xyz="0 0 0" rpy="0 0 0" />
            </collision>
            <inertial>
                <origin xyz="0 0 0" rpy="0 0 0" />
                <mass value="0.1" />
                <inertia ixx="0.1" ixy="0" ixz="0"
                        iyy="0.1" iyz="0"
                        izz="0.1" />
            </inertial> 
    </link>

    <link name="lidar_sensor" />

    <joint name="lidar_joint" type="fixed" >
        <parent link="base_link" />
        <child link="lidar_link" />
        <origin xyz="0 0 0.075" rpy="0 0 0" />
    </joint>

    <joint name="lidar_sensor_joint" type="fixed" >
        <parent link="lidar_link" />
        <child link="lidar_sensor" />
        <origin xyz="0 0 0" rpy="0 0 0" />
    </joint>


    <link name="camera_link">
    </link>

    <joint name="base_camera_joint" type="fixed">
        <parent link="base_link" />
        <child link="camera_link" />
        <origin xyz="0.125 0 0.03" rpy="0 0 0" />
    </joint>

    <link name="camera_optical_link" />

    <joint name="camera_optical_joint" type="fixed">
        <origin xyz="0 0 0" rpy="-1.57 0 -1.57"/>
        <parent link="camera_link"/>
        <child link="camera_optical_link"/>
    </joint>

</robot>