<?xml version="1.0" encoding="utf-8"?>
<robot
  name="scorbot">
  <link
    name="base_link">
    <inertial>
      <origin
        xyz="3.57353036051222E-16 0 0.0959467613422253"
        rpy="0 0 0" />
      <mass
        value="44.2535272283148" />
      <inertia
        ixx="0.247896294723323"
        ixy="-4.16333634234434E-17"
        ixz="-3.79623896820991E-16"
        iyy="0.247896294723323"
        iyz="6.12958935067386E-17"
        izz="0.212101712141814" />
    </inertial>
    <visual>
      <origin
        xyz="0 0 0"
        rpy="0 0 0" />
      <geometry>
        <mesh
          filename="package://scorbot_description/meshes/base_link.STL" />
      </geometry>
      <material
        name="yellow">
        <color
          rgba="0.529411764705882 0.549019607843137 0.549019607843137 1" />
      </material>
    </visual>
    <collision>
      <origin
        xyz="0 0 0"
        rpy="0 0 0" />
      <geometry>
        <mesh
          filename="package://scorbot_description/meshes/base_link.STL" />
      </geometry>
    </collision>
  </link>
  <link
    name="Link_1">
    <inertial>
      <origin
        xyz="-0.0393024891683798 1.38777878078145E-16 -0.0874617547525774"
        rpy="0 0 0" />
      <mass
        value="5.94250216126264" />
      <inertia
        ixx="0.0488063937041339"
        ixy="5.5944832100252E-17"
        ixz="0.00772319680952084"
        iyy="0.0448674445167095"
        iyz="6.00070153152218E-17"
        izz="0.0629004503463325" />
    </inertial>
    <visual>
      <origin
        xyz="0 0 0"
        rpy="0 0 0" />
      <geometry>
        <mesh
          filename="package://scorbot_description/meshes/Link_1.STL" />
      </geometry>
      <material
        name="blue">
        <color
          rgba="0.529411764705882 0.549019607843137 0.549019607843137 1" />
      </material>
    </visual>
    <collision>
      <origin
        xyz="0 0 0"
        rpy="0 0 0" />
      <geometry>
        <mesh
          filename="package://scorbot_description/meshes/Link_1.STL" />
      </geometry>
    </collision>
  </link>
  <joint
    name="joint_1"
    type="revolute">
    <origin
      xyz="0 0 0.362"
      rpy="0 0 0" />
    <parent
      link="base_link" />
    <child
      link="Link_1" />
    <axis
      xyz="0 0 1" />
    <limit
      lower="0"
      upper="1.5708"
      effort="10"
      velocity="2" />
  </joint>
  <link
    name="Link_2">
    <inertial>
      <origin
        xyz="-0.00962335232420992 8.32667268468867E-17 0.0786981470078051"
        rpy="0 0 0" />
      <mass
        value="5.92901497084969" />
      <inertia
        ixx="0.0204163441806219"
        ixy="-6.50521303491303E-19"
        ixz="2.23710864908789E-17"
        iyy="0.0149522802458732"
        iyz="7.27587289552345E-18"
        izz="0.00762399978976403" />
    </inertial>
    <visual>
      <origin
        xyz="0 0 0"
        rpy="0 0 0" />
      <geometry>
        <mesh
          filename="package://scorbot_description/meshes/Link_2.STL" />
      </geometry>
      <material
        name="black">
        <color
          rgba="0.529411764705882 0.549019607843137 0.549019607843137 1" />
      </material>
    </visual>
    <collision>
      <origin
        xyz="0 0 0"
        rpy="0 0 0" />
      <geometry>
        <mesh
          filename="package://scorbot_description/meshes/Link_2.STL" />
      </geometry>
    </collision>
  </link>
  <joint
    name="joint_2"
    type="revolute">
    <origin
      xyz="0 0 0"
      rpy="0 0 0" />
    <parent
      link="Link_1" />
    <child
      link="Link_2" />
    <axis
      xyz="0 1 0" />
    <limit
      lower="0"
      upper="1.5708"
      effort="10"
      velocity="2" />
  </joint>
  <link
    name="Link_3">
    <inertial>
      <origin
        xyz="-0.00667311688772381 -1.66533453693773E-16 0.0732055879080055"
        rpy="0 0 0" />
      <mass
        value="4.84788451098674" />
      <inertia
        ixx="0.0164706779946934"
        ixy="6.50521303491303E-19"
        ixz="2.22922656348282E-17"
        iyy="0.011735256889825"
        iyz="-1.5894285408225E-19"
        izz="0.00623253485779257" />
    </inertial>
    <visual>
      <origin
        xyz="0 0 0"
        rpy="0 0 0" />
      <geometry>
        <mesh
          filename="package://scorbot_description/meshes/Link_3.STL" />
      </geometry>
      <material
        name="green">
        <color
          rgba="0.529411764705882 0.549019607843137 0.549019607843137 1" />
      </material>
    </visual>
    <collision>
      <origin
        xyz="0 0 0"
        rpy="0 0 0" />
      <geometry>
        <mesh
          filename="package://scorbot_description/meshes/Link_3.STL" />
      </geometry>
    </collision>
  </link>
  <joint
    name="joint_3"
    type="revolute">
    <origin
      xyz="0 0 0.22"
      rpy="0 0 0" />
    <parent
      link="Link_2" />
    <child
      link="Link_3" />
    <axis
      xyz="0 1 0" />
    <limit
      lower="0"
      upper="1.5708"
      effort="10"
      velocity="2" />
  </joint>
  <link
    name="Link_4">
    <inertial>
      <origin
        xyz="1.95850198032553E-05 1.1685798894906E-05 0.0164517277716482"
        rpy="0 0 0" />
      <mass
        value="2.84057550912738" />
      <inertia
        ixx="0.00120052693410438"
        ixy="-4.75839738434385E-12"
        ixz="-6.3328563496909E-12"
        iyy="0.00109014194402835"
        iyz="-9.59491723665103E-08"
        izz="0.000658884515276176" />
    </inertial>
    <visual>
      <origin
        xyz="0 0 0"
        rpy="0 0 0" />
      <geometry>
        <mesh
          filename="package://scorbot_description/meshes/Link_4.STL" />
      </geometry>
      <material
        name="red">
        <color
          rgba="0.529411764705882 0.549019607843137 0.549019607843137 1" />
      </material>
    </visual>
    <collision>
      <origin
        xyz="0 0 0"
        rpy="0 0 0" />
      <geometry>
        <mesh
          filename="package://scorbot_description/meshes/Link_4.STL" />
      </geometry>
    </collision>
  </link>
  <joint
    name="joint_4"
    type="revolute">
    <origin
      xyz="0 0 0.22"
      rpy="0 0 0" />
    <parent
      link="Link_3" />
    <child
      link="Link_4" />
    <axis
      xyz="0 1 0" />
    <limit
      lower="0"
      upper="1.5708"
      effort="10"
      velocity="2" />
  </joint>
  
</robot>
